<?xml version="1.0" ?>
<!-- =================================================================================== -->
<!-- |    This document was autogenerated by xacro from robot.xacro                    | -->
<!-- |    EDITING THIS FILE BY HAND IS NOT RECOMMENDED                                 | -->
<!-- =================================================================================== -->
<robot name="locotouch">
  <material name="black">
    <color rgba="0.0 0.0 0.0 1.0"/>
  </material>
  <material name="blue">
    <color rgba="0.0 0.0 0.8 1.0"/>
  </material>
  <material name="green">
    <color rgba="0.0 0.8 0.0 1.0"/>
  </material>
  <material name="grey">
    <color rgba="0.2 0.2 0.2 1.0"/>
  </material>
  <material name="silver">
    <color rgba="0.9137254901960784 0.9137254901960784 0.8470588235294118 1.0"/>
  </material>
  <material name="orange">
    <color rgba="1.0 0.4235294117647059 0.0392156862745098 1.0"/>
  </material>
  <material name="brown">
    <color rgba="0.8705882352941177 0.8117647058823529 0.7647058823529411 1.0"/>
  </material>
  <material name="red">
    <color rgba="0.8 0.0 0.0 1.0"/>
  </material>
  <material name="white">
    <color rgba="1.0 1.0 1.0 1.0"/>
  </material>

  <link name="trunk">
    <visual>
      <origin rpy="0 0 0" xyz="0 0 0"/>
      <geometry>
        <mesh filename="../meshes/trunk.stl" scale="1 1 1"/>
      </geometry>
      <material name="silver"/>
    </visual>
    <collision>
      <origin rpy="0 0 0" xyz="0 0 0"/>
      <geometry>
        <box size="0.256 0.1 0.114"/>
      </geometry>
    </collision>
    <inertial>
      <origin rpy="0 0 0" xyz="0.0223 0.002 -0.0005"/>
      <mass value="5.204"/>
      <inertia ixx="0.0168128557" ixy="-0.0002296769" ixz="-0.0002945293" iyy="0.063009565" iyz="-4.18731e-05" izz="0.0716547275"/>
    </inertial>
  </link>

  <joint name="1_FR_hip_joint" type="revolute">
    <origin rpy="0 0 0" xyz="0.1881 -0.04675 0"/>
    <parent link="trunk"/>
    <child link="1_FR_hip"/>
    <axis xyz="1 0 0"/>
    <dynamics damping="0.0" friction="0.0"/>
    <limit effort="23.7" lower="-0.863" upper="0.863" velocity="30.1"/>
  </joint>
  <joint name="1_FR_hip_rotor_joint" type="fixed">
    <origin rpy="0 0 0" xyz="0.11215 -0.04675 0"/>
    <parent link="trunk"/>
    <child link="1_FR_hip_rotor"/>
  </joint>
  <link name="1_FR_hip">
    <visual>
      <origin rpy="3.141592653589793 0 0" xyz="0 0 0"/>
      <geometry>
        <mesh filename="../meshes/hip.stl" scale="1 1 1"/>
      </geometry>
      <material name="silver"/>
    </visual>
    <collision>
      <origin rpy="1.5707963267948966 0 0" xyz="0 -0.08 0"/>
      <geometry>
        <cylinder length="0.04" radius="0.046"/>
      </geometry>
    </collision>
    <inertial>
      <origin rpy="0 0 0" xyz="-0.005657 0.008752 -0.000102"/>
      <mass value="0.591"/>
      <inertia ixx="0.000334008405" ixy="1.0826066e-05" ixz="1.290732e-06" iyy="0.000619101213" iyz="-1.643194e-06" izz="0.00040057614"/>
    </inertial>
  </link>
  <link name="1_FR_hip_rotor">
    <collision>
      <origin rpy="0 1.5707963267948966 0" xyz="0 0 0"/>
      <geometry>
        <cylinder length="0.02" radius="0.035"/>
      </geometry>
    </collision>
    <inertial>
      <origin rpy="0 0 0" xyz="0.0 0.0 0.0"/>
      <mass value="0.089"/>
      <inertia ixx="0.000111842" ixy="0.0" ixz="0.0" iyy="5.9647e-05" iyz="0.0" izz="5.9647e-05"/>
    </inertial>
  </link>
  <joint name="1_FR_thigh_joint" type="revolute">
    <origin rpy="0 0 0" xyz="0 -0.08 0"/>
    <parent link="1_FR_hip"/>
    <child link="1_FR_thigh"/>
    <axis xyz="0 1 0"/>
    <dynamics damping="0.0" friction="0.0"/>
    <limit effort="23.7" lower="-0.686" upper="4.501" velocity="30.1"/>
  </joint>
  <joint name="1_FR_thigh_rotor_joint" type="fixed">
    <origin rpy="0 0 0" xyz="0.0 0.00015 0"/>
    <parent link="1_FR_hip"/>
    <child link="1_FR_thigh_rotor"/>
  </joint>
  <link name="1_FR_thigh">
    <visual>
      <origin rpy="0 0 0" xyz="0 0 0"/>
      <geometry>
        <mesh filename="../meshes/thigh_mirror.stl" scale="1 1 1"/>
      </geometry>
      <material name="silver"/>
    </visual>
    <collision>
      <origin rpy="0 1.5707963267948966 0" xyz="0 0 -0.1065"/>
      <geometry>
        <box size="0.213 0.0245 0.034"/>
      </geometry>
    </collision>
    <inertial>
      <origin rpy="0 0 0" xyz="-0.003342 0.018054 -0.033451"/>
      <mass value="0.92"/>
      <inertia ixx="0.004431760472" ixy="-5.7496807e-05" ixz="-0.000218457134" iyy="0.004485671726" iyz="-0.000572001265" izz="0.000740309489"/>
    </inertial>
  </link>
  <link name="1_FR_thigh_rotor">
    <collision>
      <origin rpy="1.5707963267948966 0 0" xyz="0 0 0"/>
      <geometry>
        <cylinder length="0.02" radius="0.035"/>
      </geometry>
    </collision>
    <inertial>
      <origin rpy="0 0 0" xyz="0.0 0.0 0.0"/>
      <mass value="0.089"/>
      <inertia ixx="5.9647e-05" ixy="0.0" ixz="0.0" iyy="0.000111842" iyz="0.0" izz="5.9647e-05"/>
    </inertial>
  </link>
  <joint name="1_FR_calf_joint" type="revolute">
    <origin rpy="0 0 0" xyz="0 0 -0.213"/>
    <parent link="1_FR_thigh"/>
    <child link="1_FR_calf"/>
    <axis xyz="0 1 0"/>
    <dynamics damping="0.0" friction="0.0"/>
    <limit effort="35.55" lower="-2.818" upper="-0.888" velocity="20.06"/>
  </joint>
  <joint name="1_FR_calf_rotor_joint" type="fixed">
    <origin rpy="0 0 0" xyz="0.0 0.03235 0"/>
    <parent link="1_FR_thigh"/>
    <child link="1_FR_calf_rotor"/>
  </joint>
  <link name="1_FR_calf">
    <visual>
      <origin rpy="0 0 0" xyz="0 0 0"/>
      <geometry>
        <mesh filename="../meshes/calf.stl" scale="1 1 1"/>
      </geometry>
      <material name="silver"/>
    </visual>
    <collision>
      <origin rpy="0 1.5707963267948966 0" xyz="0 0 -0.1065"/>
      <geometry>
        <box size="0.213 0.016 0.016"/>
      </geometry>
    </collision>
    <inertial>
      <origin rpy="0 0 0" xyz="0.006197 0.001408 -0.116695"/>
      <mass value="0.135862"/>
      <inertia ixx="0.001088793059" ixy="-2.55679e-07" ixz="7.117814e-06" iyy="0.001100428748" iyz="2.077264e-06" izz="2.4787446e-05"/>
    </inertial>
  </link>
  <link name="1_FR_calf_rotor">
    <collision>
      <origin rpy="1.5707963267948966 0 0" xyz="0 0 0"/>
      <geometry>
        <cylinder length="0.02" radius="0.035"/>
      </geometry>
    </collision>
    <inertial>
      <origin rpy="0 0 0" xyz="0.0 0.0 0.0"/>
      <mass value="0.089"/>
      <inertia ixx="5.9647e-05" ixy="0.0" ixz="0.0" iyy="0.000111842" iyz="0.0" izz="5.9647e-05"/>
    </inertial>
  </link>
  <joint name="1_FR_foot_fixed" type="fixed" dont_collapse="true">
    <origin rpy="0 0 0" xyz="0 0 -0.213"/>
    <parent link="1_FR_calf"/>
    <child link="1_FR_foot"/>
  </joint>
  <link name="1_FR_foot">
    <visual>
      <origin rpy="0 0 0" xyz="0 0 0"/>
      <geometry>
        <sphere radius="0.01"/>
      </geometry>
      <material name="silver"/>
    </visual>
    <collision>
      <origin rpy="0 0 0" xyz="0 0 0"/>
      <geometry>
        <sphere radius="0.02"/>
      </geometry>
    </collision>
    <inertial>
      <mass value="0.06"/>
      <inertia ixx="9.600000000000001e-06" ixy="0.0" ixz="0.0" iyy="9.600000000000001e-06" iyz="0.0" izz="9.600000000000001e-06"/>
    </inertial>
  </link>

  <joint name="2_FL_hip_joint" type="revolute">
    <origin rpy="0 0 0" xyz="0.1881 0.04675 0"/>
    <parent link="trunk"/>
    <child link="2_FL_hip"/>
    <axis xyz="1 0 0"/>
    <dynamics damping="0.0" friction="0.0"/>
    <limit effort="23.7" lower="-0.863" upper="0.863" velocity="30.1"/>
  </joint>
  <joint name="2_FL_hip_rotor_joint" type="fixed">
    <origin rpy="0 0 0" xyz="0.11215 0.04675 0"/>
    <parent link="trunk"/>
    <child link="2_FL_hip_rotor"/>
  </joint>
  <link name="2_FL_hip">
    <visual>
      <origin rpy="0 0 0" xyz="0 0 0"/>
      <geometry>
        <mesh filename="../meshes/hip.stl" scale="1 1 1"/>
      </geometry>
      <material name="silver"/>
    </visual>
    <collision>
      <origin rpy="1.5707963267948966 0 0" xyz="0 0.08 0"/>
      <geometry>
        <cylinder length="0.04" radius="0.046"/>
      </geometry>
    </collision>
    <inertial>
      <origin rpy="0 0 0" xyz="-0.005657 -0.008752 -0.000102"/>
      <mass value="0.591"/>
      <inertia ixx="0.000334008405" ixy="-1.0826066e-05" ixz="1.290732e-06" iyy="0.000619101213" iyz="1.643194e-06" izz="0.00040057614"/>
    </inertial>
  </link>
  <link name="2_FL_hip_rotor">
    <collision>
      <origin rpy="0 1.5707963267948966 0" xyz="0 0 0"/>
      <geometry>
        <cylinder length="0.02" radius="0.035"/>
      </geometry>
    </collision>
    <inertial>
      <origin rpy="0 0 0" xyz="0.0 0.0 0.0"/>
      <mass value="0.089"/>
      <inertia ixx="0.000111842" ixy="0.0" ixz="0.0" iyy="5.9647e-05" iyz="0.0" izz="5.9647e-05"/>
    </inertial>
  </link>
  <joint name="2_FL_thigh_joint" type="revolute">
    <origin rpy="0 0 0" xyz="0 0.08 0"/>
    <parent link="2_FL_hip"/>
    <child link="2_FL_thigh"/>
    <axis xyz="0 1 0"/>
    <dynamics damping="0.0" friction="0.0"/>
    <limit effort="23.7" lower="-0.686" upper="4.501" velocity="30.1"/>
  </joint>
  <joint name="2_FL_thigh_rotor_joint" type="fixed">
    <origin rpy="0 0 0" xyz="0.0 -0.00015 0"/>
    <parent link="2_FL_hip"/>
    <child link="2_FL_thigh_rotor"/>
  </joint>
  <link name="2_FL_thigh">
    <visual>
      <origin rpy="0 0 0" xyz="0 0 0"/>
      <geometry>
        <mesh filename="../meshes/thigh.stl" scale="1 1 1"/>
      </geometry>
      <material name="silver"/>
    </visual>
    <collision>
      <origin rpy="0 1.5707963267948966 0" xyz="0 0 -0.1065"/>
      <geometry>
        <box size="0.213 0.0245 0.034"/>
      </geometry>
    </collision>
    <inertial>
      <origin rpy="0 0 0" xyz="-0.003342 -0.018054 -0.033451"/>
      <mass value="0.92"/>
      <inertia ixx="0.004431760472" ixy="5.7496807e-05" ixz="-0.000218457134" iyy="0.004485671726" iyz="0.000572001265" izz="0.000740309489"/>
    </inertial>
  </link>
  <link name="2_FL_thigh_rotor">
    <collision>
      <origin rpy="1.5707963267948966 0 0" xyz="0 0 0"/>
      <geometry>
        <cylinder length="0.02" radius="0.035"/>
      </geometry>
    </collision>
    <inertial>
      <origin rpy="0 0 0" xyz="0.0 0.0 0.0"/>
      <mass value="0.089"/>
      <inertia ixx="5.9647e-05" ixy="0.0" ixz="0.0" iyy="0.000111842" iyz="0.0" izz="5.9647e-05"/>
    </inertial>
  </link>
  <joint name="2_FL_calf_joint" type="revolute">
    <origin rpy="0 0 0" xyz="0 0 -0.213"/>
    <parent link="2_FL_thigh"/>
    <child link="2_FL_calf"/>
    <axis xyz="0 1 0"/>
    <dynamics damping="0.0" friction="0.0"/>
    <limit effort="35.55" lower="-2.818" upper="-0.888" velocity="20.06"/>
  </joint>
  <joint name="2_FL_calf_rotor_joint" type="fixed">
    <origin rpy="0 0 0" xyz="0.0 -0.03235 0"/>
    <parent link="2_FL_thigh"/>
    <child link="2_FL_calf_rotor"/>
  </joint>
  <link name="2_FL_calf">
    <visual>
      <origin rpy="0 0 0" xyz="0 0 0"/>
      <geometry>
        <mesh filename="../meshes/calf.stl" scale="1 1 1"/>
      </geometry>
      <material name="silver"/>
    </visual>
    <collision>
      <origin rpy="0 1.5707963267948966 0" xyz="0 0 -0.1065"/>
      <geometry>
        <box size="0.213 0.016 0.016"/>
      </geometry>
    </collision>
    <inertial>
      <origin rpy="0 0 0" xyz="0.006197 0.001408 -0.116695"/>
      <mass value="0.135862"/>
      <inertia ixx="0.001088793059" ixy="-2.55679e-07" ixz="7.117814e-06" iyy="0.001100428748" iyz="2.077264e-06" izz="2.4787446e-05"/>
    </inertial>
  </link>
  <link name="2_FL_calf_rotor">
    <collision>
      <origin rpy="1.5707963267948966 0 0" xyz="0 0 0"/>
      <geometry>
        <cylinder length="0.02" radius="0.035"/>
      </geometry>
    </collision>
    <inertial>
      <origin rpy="0 0 0" xyz="0.0 0.0 0.0"/>
      <mass value="0.089"/>
      <inertia ixx="5.9647e-05" ixy="0.0" ixz="0.0" iyy="0.000111842" iyz="0.0" izz="5.9647e-05"/>
    </inertial>
  </link>
  <joint name="2_FL_foot_fixed" type="fixed" dont_collapse="true">
    <origin rpy="0 0 0" xyz="0 0 -0.213"/>
    <parent link="2_FL_calf"/>
    <child link="2_FL_foot"/>
  </joint>
  <link name="2_FL_foot">
    <visual>
      <origin rpy="0 0 0" xyz="0 0 0"/>
      <geometry>
        <sphere radius="0.01"/>
      </geometry>
      <material name="silver"/>
    </visual>
    <collision>
      <origin rpy="0 0 0" xyz="0 0 0"/>
      <geometry>
        <sphere radius="0.02"/>
      </geometry>
    </collision>
    <inertial>
      <mass value="0.06"/>
      <inertia ixx="9.600000000000001e-06" ixy="0.0" ixz="0.0" iyy="9.600000000000001e-06" iyz="0.0" izz="9.600000000000001e-06"/>
    </inertial>
  </link>

  <joint name="3_RR_hip_joint" type="revolute">
    <origin rpy="0 0 0" xyz="-0.1881 -0.04675 0"/>
    <parent link="trunk"/>
    <child link="3_RR_hip"/>
    <axis xyz="1 0 0"/>
    <dynamics damping="0.0" friction="0.0"/>
    <limit effort="23.7" lower="-0.863" upper="0.863" velocity="30.1"/>
  </joint>
  <joint name="3_RR_hip_rotor_joint" type="fixed">
    <origin rpy="0 0 0" xyz="-0.11215 -0.04675 0"/>
    <parent link="trunk"/>
    <child link="3_RR_hip_rotor"/>
  </joint>
  <link name="3_RR_hip">
    <visual>
      <origin rpy="3.141592653589793 3.141592653589793 0" xyz="0 0 0"/>
      <geometry>
        <mesh filename="../meshes/hip.stl" scale="1 1 1"/>
      </geometry>
      <material name="silver"/>
    </visual>
    <collision>
      <origin rpy="1.5707963267948966 0 0" xyz="0 -0.08 0"/>
      <geometry>
        <cylinder length="0.04" radius="0.046"/>
      </geometry>
    </collision>
    <inertial>
      <origin rpy="0 0 0" xyz="0.005657 0.008752 -0.000102"/>
      <mass value="0.591"/>
      <inertia ixx="0.000334008405" ixy="-1.0826066e-05" ixz="-1.290732e-06" iyy="0.000619101213" iyz="-1.643194e-06" izz="0.00040057614"/>
    </inertial>
  </link>
  <link name="3_RR_hip_rotor">
    <collision>
      <origin rpy="0 1.5707963267948966 0" xyz="0 0 0"/>
      <geometry>
        <cylinder length="0.02" radius="0.035"/>
      </geometry>
    </collision>
    <inertial>
      <origin rpy="0 0 0" xyz="0.0 0.0 0.0"/>
      <mass value="0.089"/>
      <inertia ixx="0.000111842" ixy="0.0" ixz="0.0" iyy="5.9647e-05" iyz="0.0" izz="5.9647e-05"/>
    </inertial>
  </link>
  <joint name="3_RR_thigh_joint" type="revolute">
    <origin rpy="0 0 0" xyz="0 -0.08 0"/>
    <parent link="3_RR_hip"/>
    <child link="3_RR_thigh"/>
    <axis xyz="0 1 0"/>
    <dynamics damping="0.0" friction="0.0"/>
    <limit effort="23.7" lower="-0.686" upper="4.501" velocity="30.1"/>
  </joint>
  <joint name="3_RR_thigh_rotor_joint" type="fixed">
    <origin rpy="0 0 0" xyz="0.0 0.00015 0"/>
    <parent link="3_RR_hip"/>
    <child link="3_RR_thigh_rotor"/>
  </joint>
  <link name="3_RR_thigh">
    <visual>
      <origin rpy="0 0 0" xyz="0 0 0"/>
      <geometry>
        <mesh filename="../meshes/thigh_mirror.stl" scale="1 1 1"/>
      </geometry>
      <material name="silver"/>
    </visual>
    <collision>
      <origin rpy="0 1.5707963267948966 0" xyz="0 0 -0.1065"/>
      <geometry>
        <box size="0.213 0.0245 0.034"/>
      </geometry>
    </collision>
    <inertial>
      <origin rpy="0 0 0" xyz="-0.003342 0.018054 -0.033451"/>
      <mass value="0.92"/>
      <inertia ixx="0.004431760472" ixy="-5.7496807e-05" ixz="-0.000218457134" iyy="0.004485671726" iyz="-0.000572001265" izz="0.000740309489"/>
    </inertial>
  </link>
  <link name="3_RR_thigh_rotor">
    <collision>
      <origin rpy="1.5707963267948966 0 0" xyz="0 0 0"/>
      <geometry>
        <cylinder length="0.02" radius="0.035"/>
      </geometry>
    </collision>
    <inertial>
      <origin rpy="0 0 0" xyz="0.0 0.0 0.0"/>
      <mass value="0.089"/>
      <inertia ixx="5.9647e-05" ixy="0.0" ixz="0.0" iyy="0.000111842" iyz="0.0" izz="5.9647e-05"/>
    </inertial>
  </link>
  <joint name="3_RR_calf_joint" type="revolute">
    <origin rpy="0 0 0" xyz="0 0 -0.213"/>
    <parent link="3_RR_thigh"/>
    <child link="3_RR_calf"/>
    <axis xyz="0 1 0"/>
    <dynamics damping="0.0" friction="0.0"/>
    <limit effort="35.55" lower="-2.818" upper="-0.888" velocity="20.06"/>
  </joint>
  <joint name="3_RR_calf_rotor_joint" type="fixed">
    <origin rpy="0 0 0" xyz="0.0 0.03235 0"/>
    <parent link="3_RR_thigh"/>
    <child link="3_RR_calf_rotor"/>
  </joint>
  <link name="3_RR_calf">
    <visual>
      <origin rpy="0 0 0" xyz="0 0 0"/>
      <geometry>
        <mesh filename="../meshes/calf.stl" scale="1 1 1"/>
      </geometry>
      <material name="silver"/>
    </visual>
    <collision>
      <origin rpy="0 1.5707963267948966 0" xyz="0 0 -0.1065"/>
      <geometry>
        <box size="0.213 0.016 0.016"/>
      </geometry>
    </collision>
    <inertial>
      <origin rpy="0 0 0" xyz="0.006197 0.001408 -0.116695"/>
      <mass value="0.135862"/>
      <inertia ixx="0.001088793059" ixy="-2.55679e-07" ixz="7.117814e-06" iyy="0.001100428748" iyz="2.077264e-06" izz="2.4787446e-05"/>
    </inertial>
  </link>
  <link name="3_RR_calf_rotor">
    <collision>
      <origin rpy="1.5707963267948966 0 0" xyz="0 0 0"/>
      <geometry>
        <cylinder length="0.02" radius="0.035"/>
      </geometry>
    </collision>
    <inertial>
      <origin rpy="0 0 0" xyz="0.0 0.0 0.0"/>
      <mass value="0.089"/>
      <inertia ixx="5.9647e-05" ixy="0.0" ixz="0.0" iyy="0.000111842" iyz="0.0" izz="5.9647e-05"/>
    </inertial>
  </link>
  <joint name="3_RR_foot_fixed" type="fixed" dont_collapse="true">
    <origin rpy="0 0 0" xyz="0 0 -0.213"/>
    <parent link="3_RR_calf"/>
    <child link="3_RR_foot"/>
  </joint>
  <link name="3_RR_foot">
    <visual>
      <origin rpy="0 0 0" xyz="0 0 0"/>
      <geometry>
        <sphere radius="0.01"/>
      </geometry>
      <material name="silver"/>
    </visual>
    <collision>
      <origin rpy="0 0 0" xyz="0 0 0"/>
      <geometry>
        <sphere radius="0.02"/>
      </geometry>
    </collision>
    <inertial>
      <mass value="0.06"/>
      <inertia ixx="9.600000000000001e-06" ixy="0.0" ixz="0.0" iyy="9.600000000000001e-06" iyz="0.0" izz="9.600000000000001e-06"/>
    </inertial>
  </link>

  <joint name="4_RL_hip_joint" type="revolute">
    <origin rpy="0 0 0" xyz="-0.1881 0.04675 0"/>
    <parent link="trunk"/>
    <child link="4_RL_hip"/>
    <axis xyz="1 0 0"/>
    <dynamics damping="0.0" friction="0.0"/>
    <limit effort="23.7" lower="-0.863" upper="0.863" velocity="30.1"/>
  </joint>
  <joint name="4_RL_hip_rotor_joint" type="fixed">
    <origin rpy="0 0 0" xyz="-0.11215 0.04675 0"/>
    <parent link="trunk"/>
    <child link="4_RL_hip_rotor"/>
  </joint>
  <link name="4_RL_hip">
    <visual>
      <origin rpy="0 3.141592653589793 0" xyz="0 0 0"/>
      <geometry>
        <mesh filename="../meshes/hip.stl" scale="1 1 1"/>
      </geometry>
      <material name="silver"/>
    </visual>
    <collision>
      <origin rpy="1.5707963267948966 0 0" xyz="0 0.08 0"/>
      <geometry>
        <cylinder length="0.04" radius="0.046"/>
      </geometry>
    </collision>
    <inertial>
      <origin rpy="0 0 0" xyz="0.005657 -0.008752 -0.000102"/>
      <mass value="0.591"/>
      <inertia ixx="0.000334008405" ixy="1.0826066e-05" ixz="-1.290732e-06" iyy="0.000619101213" iyz="1.643194e-06" izz="0.00040057614"/>
    </inertial>
  </link>
  <link name="4_RL_hip_rotor">
    <collision>
      <origin rpy="0 1.5707963267948966 0" xyz="0 0 0"/>
      <geometry>
        <cylinder length="0.02" radius="0.035"/>
      </geometry>
    </collision>
    <inertial>
      <origin rpy="0 0 0" xyz="0.0 0.0 0.0"/>
      <mass value="0.089"/>
      <inertia ixx="0.000111842" ixy="0.0" ixz="0.0" iyy="5.9647e-05" iyz="0.0" izz="5.9647e-05"/>
    </inertial>
  </link>
  <joint name="4_RL_thigh_joint" type="revolute">
    <origin rpy="0 0 0" xyz="0 0.08 0"/>
    <parent link="4_RL_hip"/>
    <child link="4_RL_thigh"/>
    <axis xyz="0 1 0"/>
    <dynamics damping="0.0" friction="0.0"/>
    <limit effort="23.7" lower="-0.686" upper="4.501" velocity="30.1"/>
  </joint>
  <joint name="4_RL_thigh_rotor_joint" type="fixed">
    <origin rpy="0 0 0" xyz="0.0 -0.00015 0"/>
    <parent link="4_RL_hip"/>
    <child link="4_RL_thigh_rotor"/>
  </joint>
  <link name="4_RL_thigh">
    <visual>
      <origin rpy="0 0 0" xyz="0 0 0"/>
      <geometry>
        <mesh filename="../meshes/thigh.stl" scale="1 1 1"/>
      </geometry>
      <material name="silver"/>
    </visual>
    <collision>
      <origin rpy="0 1.5707963267948966 0" xyz="0 0 -0.1065"/>
      <geometry>
        <box size="0.213 0.0245 0.034"/>
      </geometry>
    </collision>
    <inertial>
      <origin rpy="0 0 0" xyz="-0.003342 -0.018054 -0.033451"/>
      <mass value="0.92"/>
      <inertia ixx="0.004431760472" ixy="5.7496807e-05" ixz="-0.000218457134" iyy="0.004485671726" iyz="0.000572001265" izz="0.000740309489"/>
    </inertial>
  </link>
  <link name="4_RL_thigh_rotor">
    <collision>
      <origin rpy="1.5707963267948966 0 0" xyz="0 0 0"/>
      <geometry>
        <cylinder length="0.02" radius="0.035"/>
      </geometry>
    </collision>
    <inertial>
      <origin rpy="0 0 0" xyz="0.0 0.0 0.0"/>
      <mass value="0.089"/>
      <inertia ixx="5.9647e-05" ixy="0.0" ixz="0.0" iyy="0.000111842" iyz="0.0" izz="5.9647e-05"/>
    </inertial>
  </link>
  <joint name="4_RL_calf_joint" type="revolute">
    <origin rpy="0 0 0" xyz="0 0 -0.213"/>
    <parent link="4_RL_thigh"/>
    <child link="4_RL_calf"/>
    <axis xyz="0 1 0"/>
    <dynamics damping="0.0" friction="0.0"/>
    <limit effort="35.55" lower="-2.818" upper="-0.888" velocity="20.06"/>
  </joint>
  <joint name="4_RL_calf_rotor_joint" type="fixed">
    <origin rpy="0 0 0" xyz="0.0 -0.03235 0"/>
    <parent link="4_RL_thigh"/>
    <child link="4_RL_calf_rotor"/>
  </joint>
  <link name="4_RL_calf">
    <visual>
      <origin rpy="0 0 0" xyz="0 0 0"/>
      <geometry>
        <mesh filename="../meshes/calf.stl" scale="1 1 1"/>
      </geometry>
      <material name="silver"/>
    </visual>
    <collision>
      <origin rpy="0 1.5707963267948966 0" xyz="0 0 -0.1065"/>
      <geometry>
        <box size="0.213 0.016 0.016"/>
      </geometry>
    </collision>
    <inertial>
      <origin rpy="0 0 0" xyz="0.006197 0.001408 -0.116695"/>
      <mass value="0.135862"/>
      <inertia ixx="0.001088793059" ixy="-2.55679e-07" ixz="7.117814e-06" iyy="0.001100428748" iyz="2.077264e-06" izz="2.4787446e-05"/>
    </inertial>
  </link>
  <link name="4_RL_calf_rotor">
    <collision>
      <origin rpy="1.5707963267948966 0 0" xyz="0 0 0"/>
      <geometry>
        <cylinder length="0.02" radius="0.035"/>
      </geometry>
    </collision>
    <inertial>
      <origin rpy="0 0 0" xyz="0.0 0.0 0.0"/>
      <mass value="0.089"/>
      <inertia ixx="5.9647e-05" ixy="0.0" ixz="0.0" iyy="0.000111842" iyz="0.0" izz="5.9647e-05"/>
    </inertial>
  </link>
  <joint name="4_RL_foot_fixed" type="fixed" dont_collapse="true">
    <origin rpy="0 0 0" xyz="0 0 -0.213"/>
    <parent link="4_RL_calf"/>
    <child link="4_RL_foot"/>
  </joint>
  <link name="4_RL_foot">
    <visual>
      <origin rpy="0 0 0" xyz="0 0 0"/>
      <geometry>
        <sphere radius="0.01"/>
      </geometry>
      <material name="silver"/>
    </visual>
    <collision>
      <origin rpy="0 0 0" xyz="0 0 0"/>
      <geometry>
        <sphere radius="0.02"/>
      </geometry>
    </collision>
    <inertial>
      <mass value="0.06"/>
      <inertia ixx="9.600000000000001e-06" ixy="0.0" ixz="0.0" iyy="9.600000000000001e-06" iyz="0.0" izz="9.600000000000001e-06"/>
    </inertial>
  </link>


  <link name="back">
    <visual>
      <origin rpy="0 0 0" xyz="0 0 0"/>
      <geometry>
        <box size="0.25 0.174 0.01"/>
      </geometry>
      <material name="silver"/>
    </visual>
    <collision>
      <origin rpy="0 0 0" xyz="0 0 0"/>
      <geometry>
        <box size="0.25 0.174 0.01"/>
      </geometry>
    </collision>
    <inertial>
      <origin rpy="0 0 0" xyz="0.0 0.0 0.0"/>
      <mass value="0.4"/>
      <inertia ixx="0.0001" ixy="0.0001" ixz="0.0001" iyy="0.0e-05" iyz="0.0e-05" izz="0.0e-05"/>
    </inertial>
  </link>
  <joint name="back_joint" type="fixed">
    <origin rpy="0 0 0" xyz="0 0 0.088"/>
    <parent link="trunk"/>
    <child link="back"/>
  </joint>

  <link name="back_mid">
    <visual>
      <origin rpy="0 0 0" xyz="0 0 0"/>
      <geometry>
        <box size="0.25 0.194 0.083"/>
      </geometry>
      <material name="silver"/>
    </visual>
    <collision>
      <origin rpy="0 0 0" xyz="0 0 0"/>
      <geometry>
        <box size="0.25 0.194 0.083"/>
      </geometry>
    </collision>
    <inertial>
      <origin rpy="0 0 0" xyz="0.0 0.0 0.01"/>
      <mass value="0.1"/>
      <inertia ixx="0.0001" ixy="0.0001" ixz="0.0001" iyy="0.0e-05" iyz="0.0e-05" izz="0.0e-05"/>
    </inertial>
  </link>
  <joint name="back_mid_joint" type="fixed">
    <origin rpy="0 0 0" xyz="0 0 0.0415"/>
    <parent link="trunk"/>
    <child link="back_mid"/>
  </joint>

  <link name="left_cylinder">
    <visual>
      <origin rpy="0 0 0" xyz="0 0 0"/>
      <geometry>
        <cylinder length="0.25" radius="0.01"/>
      </geometry>
      <material name="silver"/>
    </visual>
    <collision>
      <origin rpy="0 0 0" xyz="0 0 0"/>
      <geometry>
        <cylinder length="0.25" radius="0.01"/>
      </geometry>
    </collision>
  </link>
  <joint name="left_cylinder_joint" type="fixed">
    <origin rpy="0 1.5707963267948966 0" xyz="0 0.087 0.083"/>
    <parent link="trunk"/>
    <child link="left_cylinder"/>
  </joint>

  <link name="right_cylinder">
    <visual>
      <origin rpy="0 0 0" xyz="0 0 0"/>
      <geometry>
        <cylinder length="0.25" radius="0.01"/>
      </geometry>
      <material name="silver"/>
    </visual>
    <collision>
      <origin rpy="0 0 0" xyz="0 0 0"/>
      <geometry>
        <cylinder length="0.25" radius="0.01"/>
      </geometry>
    </collision>
  </link>
  <joint name="right_cylinder_joint" type="fixed">
    <origin rpy="0 1.5707963267948966 0" xyz="0 -0.087 0.083"/>
    <parent link="trunk"/>
    <child link="right_cylinder"/>
  </joint>

  <link name="sensor_01_01">
    <inertial>
      <origin xyz="0 -1.6653E-16 -5E-05" rpy="0 0 0" />
      <mass value="9.18E-07" />
      <inertia ixx="6.8927E-13" ixy="5.5033E-28" ixz="2.4805E-28" iyy="6.8927E-13" iyz="-3.5387E-24" izz="1.377E-12" />
    </inertial>
    <visual>
      <origin rpy="0 0 0" xyz="0 0 0"/>
      <geometry>
        <box size="0.0113 0.0105 0.001"/>
      </geometry>
      <material name="red"/>
    </visual>
    <collision>
      <origin rpy="0 0 0" xyz="0 0 0"/>
      <geometry>
        <box size="0.0183 0.0175 0.001"/>
      </geometry>
    </collision>
  </link>
  <joint name="sensor_01_01_fixed" type="fixed" dont_collapse="true">
    <origin xyz="0 0 0" rpy="0 0 0" />
    <parent link="trunk" />
    <child link="sensor_01_01" />
    <axis xyz="0 0 0" />
  </joint>

</robot>


